Workbook

Sheet Final Sam's TC Refresh
A1: Name | B1: Last known IP address | C1: MAC address | D1: fullSiteNumber | E1: Last Contact | F1: Memory Size (MB) | G1: Device Serial Number | H1: Device Type | I1: Structure Tag | J1: Site Number | K1: Physical Address | L1: Physical City | M1: Physical State | N1: Physical Zip Code | O1: Primary Phone
A2: GENSUS2BE4E7 | B2: 7.52.172.154 | C2: 040E3C2BE4E7 | D2: S06332 | E2: 46152.622 | F2: 1547 | G2: 8CG0172KG0 | H2: HP_t430 | I2: S06332.US-2016 | J2: =RIGHT(D2,4) -> 6332 | K2: =IFERROR(VLOOKUP(VALUE(J2),'Site Info'!$A:$G,3,FALSE),"") -> 1000 FRANKLIN MILLS CIR | L2: =IFERROR(VLOOKUP(VALUE(J2),'Site Info'!$A:$G,4,FALSE),"") -> PHILADELPHIA | M2: =IFERROR(VLOOKUP(VALUE(J2),'Site Info'!$A:$G,5,FALSE),"") -> PA | N2: =IFERROR(VLOOKUP(VALUE(J2),'Site Info'!$A:$G,6,FALSE),"") -> 19154-3115 | O2: =IFERROR(VLOOKUP(VALUE(J2),'Site Info'!$A:$G,7,FALSE),"") -> 2156322299
A3: GENSUS32DA9E | B3: 7.52.172.110 | C3: C4651632DA9E | D3: S06332 | E3: 46152.63 | F3: 1547 | G3: 8CG9308K62 | H3: HP_t430 | I3: S06332.US-2016 | J3: =RIGHT(D3,4) -> 6332 | K3: =IFERROR(VLOOKUP(VALUE(J3),'Site Info'!$A:$G,3,FALSE),"") -> 1000 FRANKLIN MILLS CIR | L3: =IFERROR(VLOOKUP(VALUE(J3),'Site Info'!$A:$G,4,FALSE),"") -> PHILADELPHIA | M3: =IFERROR(VLOOKUP(VALUE(J3),'Site Info'!$A:$G,5,FALSE),"") -> PA | N3: =IFERROR(VLOOKUP(VALUE(J3),'Site Info'!$A:$G,6,FALSE),"") -> 19154-3115 | O3: =IFERROR(VLOOKUP(VALUE(J3),'Site Info'!$A:$G,7,FALSE),"") -> 2156322299
A4: GENSUS2B60E6 | B4: 7.52.172.115 | C4: 040E3C2B60E6 | D4: S06332 | E4: 46153.312 | F4: 1547 | G4: 8CG0172KD0 | H4: HP_t430 | I4: S06332.US-2016 | J4: =RIGHT(D4,4) -> 6332 | K4: =IFERROR(VLOOKUP(VALUE(J4),'Site Info'!$A:$G,3,FALSE),"") -> 1000 FRANKLIN MILLS CIR | L4: =IFERROR(VLOOKUP(VALUE(J4),'Site Info'!$A:$G,4,FALSE),"") -> PHILADELPHIA | M4: =IFERROR(VLOOKUP(VALUE(J4),'Site Info'!$A:$G,5,FALSE),"") -> PA | N4: =IFERROR(VLOOKUP(VALUE(J4),'Site Info'!$A:$G,6,FALSE),"") -> 19154-3115 | O4: =IFERROR(VLOOKUP(VALUE(J4),'Site Info'!$A:$G,7,FALSE),"") -> 2156322299
A5: GENSUS2BE4BF | B5: 7.52.172.159 | C5: 040E3C2BE4BF | D5: S06332 | E5: 46153.353 | F5: 1547 | G5: 8CG0172KHF | H5: HP_t430 | I5: S06332.US-2016 | J5: =RIGHT(D5,4) -> 6332 | K5: =IFERROR(VLOOKUP(VALUE(J5),'Site Info'!$A:$G,3,FALSE),"") -> 1000 FRANKLIN MILLS CIR | L5: =IFERROR(VLOOKUP(VALUE(J5),'Site Info'!$A:$G,4,FALSE),"") -> PHILADELPHIA | M5: =IFERROR(VLOOKUP(VALUE(J5),'Site Info'!$A:$G,5,FALSE),"") -> PA | N5: =IFERROR(VLOOKUP(VALUE(J5),'Site Info'!$A:$G,6,FALSE),"") -> 19154-3115 | O5: =IFERROR(VLOOKUP(VALUE(J5),'Site Info'!$A:$G,7,FALSE),"") -> 2156322299
A6: GENSUS32DA84 | B6: 7.52.172.65 | C6: C4651632DA84 | D6: S06332 | E6: 46153.372 | F6: 1547 | G6: 8CG9308K6S | H6: HP_t430 | I6: S06332.US-2016 | J6: =RIGHT(D6,4) -> 6332 | K6: =IFERROR(VLOOKUP(VALUE(J6),'Site Info'!$A:$G,3,FALSE),"") -> 1000 FRANKLIN MILLS CIR | L6: =IFERROR(VLOOKUP(VALUE(J6),'Site Info'!$A:$G,4,FALSE),"") -> PHILADELPHIA | M6: =IFERROR(VLOOKUP(VALUE(J6),'Site Info'!$A:$G,5,FALSE),"") -> PA | N6: =IFERROR(VLOOKUP(VALUE(J6),'Site Info'!$A:$G,6,FALSE),"") -> 19154-3115 | O6: =IFERROR(VLOOKUP(VALUE(J6),'Site Info'!$A:$G,7,FALSE),"") -> 2156322299
A7: GENSUS081182 | B7: 7.52.172.64 | C7: 842AFD081182 | D7: S06332 | E7: 46153.128 | F7: 1481 | G7: 8CG107B4XT | H7: HP_t430 | I7: S06332.US-2016 | J7: =RIGHT(D7,4) -> 6332 | K7: =IFERROR(VLOOKUP(VALUE(J7),'Site Info'!$A:$G,3,FALSE),"") -> 1000 FRANKLIN MILLS CIR | L7: =IFERROR(VLOOKUP(VALUE(J7),'Site Info'!$A:$G,4,FALSE),"") -> PHILADELPHIA | M7: =IFERROR(VLOOKUP(VALUE(J7),'Site Info'!$A:$G,5,FALSE),"") -> PA | N7: =IFERROR(VLOOKUP(VALUE(J7),'Site Info'!$A:$G,6,FALSE),"") -> 19154-3115 | O7: =IFERROR(VLOOKUP(VALUE(J7),'Site Info'!$A:$G,7,FALSE),"") -> 2156322299
A8: ITCC4651632D9BE | B8: 7.52.172.112 | C8: C4651632D9BE | D8: S06332 | E8: 46152.609 | F8: 1547 | G8: 8CG9308HB4 | H8: HP_t430 | I8: S06332.US-2016 | J8: =RIGHT(D8,4) -> 6332 | K8: =IFERROR(VLOOKUP(VALUE(J8),'Site Info'!$A:$G,3,FALSE),"") -> 1000 FRANKLIN MILLS CIR | L8: =IFERROR(VLOOKUP(VALUE(J8),'Site Info'!$A:$G,4,FALSE),"") -> PHILADELPHIA | M8: =IFERROR(VLOOKUP(VALUE(J8),'Site Info'!$A:$G,5,FALSE),"") -> PA | N8: =IFERROR(VLOOKUP(VALUE(J8),'Site Info'!$A:$G,6,FALSE),"") -> 19154-3115 | O8: =IFERROR(VLOOKUP(VALUE(J8),'Site Info'!$A:$G,7,FALSE),"") -> 2156322299
A9: ITC40B034367C2C | B9: 7.84.180.20 | C9: 40B034367C2C | D9: S06410 | E9: 46151.767 | F9: 1628 | G9: 9CG71929J6 | H9: HP_t420 | I9: S06410.US-2016 | J9: =RIGHT(D9,4) -> 6410 | K9: =IFERROR(VLOOKUP(VALUE(J9),'Site Info'!$A:$G,3,FALSE),"") -> 1000 KAMEHAMEHA HWY STE 100 | L9: =IFERROR(VLOOKUP(VALUE(J9),'Site Info'!$A:$G,4,FALSE),"") -> PEARL CITY | M9: =IFERROR(VLOOKUP(VALUE(J9),'Site Info'!$A:$G,5,FALSE),"") -> HI | N9: =IFERROR(VLOOKUP(VALUE(J9),'Site Info'!$A:$G,6,FALSE),"") -> 96782-2596 | O9: =IFERROR(VLOOKUP(VALUE(J9),'Site Info'!$A:$G,7,FALSE),"") -> 8084567788
A10: GENSUS310486 | B10: 7.84.180.101 | C10: C46516310486 | D10: S06410 | E10: 46151.154 | F10: 1547 | G10: 8CG92960FF | H10: HP_t430 | I10: S06410.US-2016 | J10: =RIGHT(D10,4) -> 6410 | K10: =IFERROR(VLOOKUP(VALUE(J10),'Site Info'!$A:$G,3,FALSE),"") -> 1000 KAMEHAMEHA HWY STE 100 | L10: =IFERROR(VLOOKUP(VALUE(J10),'Site Info'!$A:$G,4,FALSE),"") -> PEARL CITY | M10: =IFERROR(VLOOKUP(VALUE(J10),'Site Info'!$A:$G,5,FALSE),"") -> HI | N10: =IFERROR(VLOOKUP(VALUE(J10),'Site Info'!$A:$G,6,FALSE),"") -> 96782-2596 | O10: =IFERROR(VLOOKUP(VALUE(J10),'Site Info'!$A:$G,7,FALSE),"") -> 8084567788
A11: GENSUS3107BC | B11: 7.84.180.172 | C11: C465163107BC | D11: S06410 | E11: 46151.702 | F11: 1547 | G11: 8CG9294ZV3 | H11: HP_t430 | I11: S06410.US-2016 | J11: =RIGHT(D11,4) -> 6410 | K11: =IFERROR(VLOOKUP(VALUE(J11),'Site Info'!$A:$G,3,FALSE),"") -> 1000 KAMEHAMEHA HWY STE 100 | L11: =IFERROR(VLOOKUP(VALUE(J11),'Site Info'!$A:$G,4,FALSE),"") -> PEARL CITY | M11: =IFERROR(VLOOKUP(VALUE(J11),'Site Info'!$A:$G,5,FALSE),"") -> HI | N11: =IFERROR(VLOOKUP(VALUE(J11),'Site Info'!$A:$G,6,FALSE),"") -> 96782-2596 | O11: =IFERROR(VLOOKUP(VALUE(J11),'Site Info'!$A:$G,7,FALSE),"") -> 8084567788
A12: GENSUS32D304 | B12: 7.84.180.23 | C12: C4651632D304 | D12: S06410 | E12: 46152.67 | F12: 1547 | G12: 8CG9308HGV | H12: HP_t430 | I12: S06410.US-2016 | J12: =RIGHT(D12,4) -> 6410 | K12: =IFERROR(VLOOKUP(VALUE(J12),'Site Info'!$A:$G,3,FALSE),"") -> 1000 KAMEHAMEHA HWY STE 100 | L12: =IFERROR(VLOOKUP(VALUE(J12),'Site Info'!$A:$G,4,FALSE),"") -> PEARL CITY | M12: =IFERROR(VLOOKUP(VALUE(J12),'Site Info'!$A:$G,5,FALSE),"") -> HI | N12: =IFERROR(VLOOKUP(VALUE(J12),'Site Info'!$A:$G,6,FALSE),"") -> 96782-2596 | O12: =IFERROR(VLOOKUP(VALUE(J12),'Site Info'!$A:$G,7,FALSE),"") -> 8084567788
A13: GENSUS310000 | B13: 7.84.180.171 | C13: C46516310000 | D13: S06410 | E13: 46152.872 | F13: 1547 | G13: 8CG9295ZP2 | H13: HP_t430 | I13: S06410.US-2016 | J13: =RIGHT(D13,4) -> 6410 | K13: =IFERROR(VLOOKUP(VALUE(J13),'Site Info'!$A:$G,3,FALSE),"") -> 1000 KAMEHAMEHA HWY STE 100 | L13: =IFERROR(VLOOKUP(VALUE(J13),'Site Info'!$A:$G,4,FALSE),"") -> PEARL CITY | M13: =IFERROR(VLOOKUP(VALUE(J13),'Site Info'!$A:$G,5,FALSE),"") -> HI | N13: =IFERROR(VLOOKUP(VALUE(J13),'Site Info'!$A:$G,6,FALSE),"") -> 96782-2596 | O13: =IFERROR(VLOOKUP(VALUE(J13),'Site Info'!$A:$G,7,FALSE),"") -> 8084567788
... A476: GENSUS168635 | B476: 7.135.132.82 | C476: 040E3C168635 | D476: S04851 | E476: 46150.625 | F476: 1547 | G476: 8CG942F40Q | H476: HP_t430 | I476: S04851.US-2016 | J476: =RIGHT(D476,4) -> 4851 | K476: =IFERROR(VLOOKUP(VALUE(J476),'Site Info'!$A:$G,3,FALSE),"") -> 1301 VETERANS PKWY | L476: =IFERROR(VLOOKUP(VALUE(J476),'Site Info'!$A:$G,4,FALSE),"") -> CLARKSVILLE | M476: =IFERROR(VLOOKUP(VALUE(J476),'Site Info'!$A:$G,5,FALSE),"") -> IN | N476: =IFERROR(VLOOKUP(VALUE(J476),'Site Info'!$A:$G,6,FALSE),"") -> 47129-7747 | O476: =IFERROR(VLOOKUP(VALUE(J476),'Site Info'!$A:$G,7,FALSE),"") -> 8122180310
A477: GENSUS1685B7 | B477: 7.135.132.17 | C477: 040E3C1685B7 | D477: S04851 | E477: 46151.044 | F477: 1547 | G477: 8CG942F3XZ | H477: HP_t430 | J477: =RIGHT(D477,4) -> 4851 | K477: =IFERROR(VLOOKUP(VALUE(J477),'Site Info'!$A:$G,3,FALSE),"") -> 1301 VETERANS PKWY | L477: =IFERROR(VLOOKUP(VALUE(J477),'Site Info'!$A:$G,4,FALSE),"") -> CLARKSVILLE | M477: =IFERROR(VLOOKUP(VALUE(J477),'Site Info'!$A:$G,5,FALSE),"") -> IN | N477: =IFERROR(VLOOKUP(VALUE(J477),'Site Info'!$A:$G,6,FALSE),"") -> 47129-7747 | O477: =IFERROR(VLOOKUP(VALUE(J477),'Site Info'!$A:$G,7,FALSE),"") -> 8122180310
A478: GENSUS168782 | B478: 7.135.132.110 | C478: 040E3C168782 | D478: S04851 | E478: 46152.63 | F478: 1547 | G478: 8CG942F3ZW | H478: HP_t430 | I478: S04851.US-2016 | J478: =RIGHT(D478,4) -> 4851 | K478: =IFERROR(VLOOKUP(VALUE(J478),'Site Info'!$A:$G,3,FALSE),"") -> 1301 VETERANS PKWY | L478: =IFERROR(VLOOKUP(VALUE(J478),'Site Info'!$A:$G,4,FALSE),"") -> CLARKSVILLE | M478: =IFERROR(VLOOKUP(VALUE(J478),'Site Info'!$A:$G,5,FALSE),"") -> IN | N478: =IFERROR(VLOOKUP(VALUE(J478),'Site Info'!$A:$G,6,FALSE),"") -> 47129-7747 | O478: =IFERROR(VLOOKUP(VALUE(J478),'Site Info'!$A:$G,7,FALSE),"") -> 8122180310
A479: GENSUS16863C | B479: 7.135.132.121 | C479: 040E3C16863C | D479: S04851 | E479: 46153.277 | F479: 1547 | G479: 8CG942F40J | H479: HP_t430 | I479: S04851.US-2016 | J479: =RIGHT(D479,4) -> 4851 | K479: =IFERROR(VLOOKUP(VALUE(J479),'Site Info'!$A:$G,3,FALSE),"") -> 1301 VETERANS PKWY | L479: =IFERROR(VLOOKUP(VALUE(J479),'Site Info'!$A:$G,4,FALSE),"") -> CLARKSVILLE | M479: =IFERROR(VLOOKUP(VALUE(J479),'Site Info'!$A:$G,5,FALSE),"") -> IN | N479: =IFERROR(VLOOKUP(VALUE(J479),'Site Info'!$A:$G,6,FALSE),"") -> 47129-7747 | O479: =IFERROR(VLOOKUP(VALUE(J479),'Site Info'!$A:$G,7,FALSE),"") -> 8122180310
A480: GENSUS167B5B | B480: 7.135.132.59 | C480: 040E3C167B5B | D480: S04851 | E480: 46153.28 | F480: 1547 | G480: 8CG942F43Q | H480: HP_t430 | I480: S04851.US-2016 | J480: =RIGHT(D480,4) -> 4851 | K480: =IFERROR(VLOOKUP(VALUE(J480),'Site Info'!$A:$G,3,FALSE),"") -> 1301 VETERANS PKWY | L480: =IFERROR(VLOOKUP(VALUE(J480),'Site Info'!$A:$G,4,FALSE),"") -> CLARKSVILLE | M480: =IFERROR(VLOOKUP(VALUE(J480),'Site Info'!$A:$G,5,FALSE),"") -> IN | N480: =IFERROR(VLOOKUP(VALUE(J480),'Site Info'!$A:$G,6,FALSE),"") -> 47129-7747 | O480: =IFERROR(VLOOKUP(VALUE(J480),'Site Info'!$A:$G,7,FALSE),"") -> 8122180310
A481: GENSUS167B89 | B481: 7.135.132.119 | C481: 040E3C167B89 | D481: S04851 | E481: 46153.348 | F481: 1547 | G481: 8CG942F436 | H481: HP_t430 | I481: S04851.US-2016 | J481: =RIGHT(D481,4) -> 4851 | K481: =IFERROR(VLOOKUP(VALUE(J481),'Site Info'!$A:$G,3,FALSE),"") -> 1301 VETERANS PKWY | L481: =IFERROR(VLOOKUP(VALUE(J481),'Site Info'!$A:$G,4,FALSE),"") -> CLARKSVILLE | M481: =IFERROR(VLOOKUP(VALUE(J481),'Site Info'!$A:$G,5,FALSE),"") -> IN | N481: =IFERROR(VLOOKUP(VALUE(J481),'Site Info'!$A:$G,6,FALSE),"") -> 47129-7747 | O481: =IFERROR(VLOOKUP(VALUE(J481),'Site Info'!$A:$G,7,FALSE),"") -> 8122180310
A482: GENSUS0839B9 | B482: 7.135.132.208 | C482: 842AFD0839B9 | D482: S04851 | E482: 46151.694 | F482: 1481 | G482: 8CG12272YD | H482: HP_t430 | I482: S04851.US-2016 | J482: =RIGHT(D482,4) -> 4851 | K482: =IFERROR(VLOOKUP(VALUE(J482),'Site Info'!$A:$G,3,FALSE),"") -> 1301 VETERANS PKWY | L482: =IFERROR(VLOOKUP(VALUE(J482),'Site Info'!$A:$G,4,FALSE),"") -> CLARKSVILLE | M482: =IFERROR(VLOOKUP(VALUE(J482),'Site Info'!$A:$G,5,FALSE),"") -> IN | N482: =IFERROR(VLOOKUP(VALUE(J482),'Site Info'!$A:$G,6,FALSE),"") -> 47129-7747 | O482: =IFERROR(VLOOKUP(VALUE(J482),'Site Info'!$A:$G,7,FALSE),"") -> 8122180310
A483: GENSUS081082 | B483: 7.135.132.77 | C483: 842AFD081082 | D483: S04851 | E483: 46153.374 | F483: 1481 | G483: 8CG107B4W6 | H483: HP_t430 | I483: S04851.US-2016 | J483: =RIGHT(D483,4) -> 4851 | K483: =IFERROR(VLOOKUP(VALUE(J483),'Site Info'!$A:$G,3,FALSE),"") -> 1301 VETERANS PKWY | L483: =IFERROR(VLOOKUP(VALUE(J483),'Site Info'!$A:$G,4,FALSE),"") -> CLARKSVILLE | M483: =IFERROR(VLOOKUP(VALUE(J483),'Site Info'!$A:$G,5,FALSE),"") -> IN | N483: =IFERROR(VLOOKUP(VALUE(J483),'Site Info'!$A:$G,6,FALSE),"") -> 47129-7747 | O483: =IFERROR(VLOOKUP(VALUE(J483),'Site Info'!$A:$G,7,FALSE),"") -> 8122180310
A484: TCTLE01 | B484: 55.135.128.31 | C484: 40B03434A762 | D484: S04851 | E484: 46153.367 | F484: 1628 | G484: 9CG7381BQK | H484: HP_t420 | I484: S04851.US-2016 | J484: =RIGHT(D484,4) -> 4851 | K484: =IFERROR(VLOOKUP(VALUE(J484),'Site Info'!$A:$G,3,FALSE),"") -> 1301 VETERANS PKWY | L484: =IFERROR(VLOOKUP(VALUE(J484),'Site Info'!$A:$G,4,FALSE),"") -> CLARKSVILLE | M484: =IFERROR(VLOOKUP(VALUE(J484),'Site Info'!$A:$G,5,FALSE),"") -> IN | N484: =IFERROR(VLOOKUP(VALUE(J484),'Site Info'!$A:$G,6,FALSE),"") -> 47129-7747 | O484: =IFERROR(VLOOKUP(VALUE(J484),'Site Info'!$A:$G,7,FALSE),"") -> 8122180310
A485: GENSUS67BEE7 | B485: 7.74.124.189 | C485: B07B2567BEE7 | D485: S06685 | E485: 46153.316 | F485: 1863 | G485: 31V4K93 | H485: DELL_WYSE_3040_THIN_CLIENT | I485: S06685.US-2016 | J485: =RIGHT(D485,4) -> 6685 | K485: =IFERROR(VLOOKUP(VALUE(J485),'Site Info'!$A:$G,3,FALSE),"") -> 1313 S UNIVERSITY AVE | L485: =IFERROR(VLOOKUP(VALUE(J485),'Site Info'!$A:$G,4,FALSE),"") -> PROVO | M485: =IFERROR(VLOOKUP(VALUE(J485),'Site Info'!$A:$G,5,FALSE),"") -> UT | N485: =IFERROR(VLOOKUP(VALUE(J485),'Site Info'!$A:$G,6,FALSE),"") -> 84601-5943 | O485: =IFERROR(VLOOKUP(VALUE(J485),'Site Info'!$A:$G,7,FALSE),"") -> 8013749700
A486: GENSUS1686D1 | B486: 7.74.124.13 | C486: 040E3C1686D1 | D486: S06685 | E486: 46151.508 | F486: 1548 | G486: 8CG942F86R | H486: HP_t430 | I486: S06685.US-2016 | J486: =RIGHT(D486,4) -> 6685 | K486: =IFERROR(VLOOKUP(VALUE(J486),'Site Info'!$A:$G,3,FALSE),"") -> 1313 S UNIVERSITY AVE | L486: =IFERROR(VLOOKUP(VALUE(J486),'Site Info'!$A:$G,4,FALSE),"") -> PROVO | M486: =IFERROR(VLOOKUP(VALUE(J486),'Site Info'!$A:$G,5,FALSE),"") -> UT | N486: =IFERROR(VLOOKUP(VALUE(J486),'Site Info'!$A:$G,6,FALSE),"") -> 84601-5943 | O486: =IFERROR(VLOOKUP(VALUE(J486),'Site Info'!$A:$G,7,FALSE),"") -> 8013749700
A487: GENSUS168670 | B487: 7.74.124.138 | C487: 040E3C168670 | D487: S06685 | E487: 46151.374 | F487: 1547 | G487: 8CG942F866 | H487: HP_t430 | I487: S06685.US-2016 | J487: =RIGHT(D487,4) -> 6685 | K487: =IFERROR(VLOOKUP(VALUE(J487),'Site Info'!$A:$G,3,FALSE),"") -> 1313 S UNIVERSITY AVE | L487: =IFERROR(VLOOKUP(VALUE(J487),'Site Info'!$A:$G,4,FALSE),"") -> PROVO | M487: =IFERROR(VLOOKUP(VALUE(J487),'Site Info'!$A:$G,5,FALSE),"") -> UT | N487: =IFERROR(VLOOKUP(VALUE(J487),'Site Info'!$A:$G,6,FALSE),"") -> 84601-5943 | O487: =IFERROR(VLOOKUP(VALUE(J487),'Site Info'!$A:$G,7,FALSE),"") -> 8013749700
A488: GENSUS1687C4 | B488: 7.74.124.17 | C488: 040E3C1687C4 | D488: S06685 | E488: 46151.396 | F488: 1547 | G488: 8CG942F882 | H488: HP_t430 | I488: S06685.US-2016 | J488: =RIGHT(D488,4) -> 6685 | K488: =IFERROR(VLOOKUP(VALUE(J488),'Site Info'!$A:$G,3,FALSE),"") -> 1313 S UNIVERSITY AVE | L488: =IFERROR(VLOOKUP(VALUE(J488),'Site Info'!$A:$G,4,FALSE),"") -> PROVO | M488: =IFERROR(VLOOKUP(VALUE(J488),'Site Info'!$A:$G,5,FALSE),"") -> UT | N488: =IFERROR(VLOOKUP(VALUE(J488),'Site Info'!$A:$G,6,FALSE),"") -> 84601-5943 | O488: =IFERROR(VLOOKUP(VALUE(J488),'Site Info'!$A:$G,7,FALSE),"") -> 8013749700
A489: GENSUS3107F4 | B489: 7.74.124.174 | C489: C465163107F4 | D489: S06685 | E489: 46152.054 | F489: 1547 | G489: 8CG929541V | H489: HP_t430 | I489: S06685.US-2016 | J489: =RIGHT(D489,4) -> 6685 | K489: =IFERROR(VLOOKUP(VALUE(J489),'Site Info'!$A:$G,3,FALSE),"") -> 1313 S UNIVERSITY AVE | L489: =IFERROR(VLOOKUP(VALUE(J489),'Site Info'!$A:$G,4,FALSE),"") -> PROVO | M489: =IFERROR(VLOOKUP(VALUE(J489),'Site Info'!$A:$G,5,FALSE),"") -> UT | N489: =IFERROR(VLOOKUP(VALUE(J489),'Site Info'!$A:$G,6,FALSE),"") -> 84601-5943 | O489: =IFERROR(VLOOKUP(VALUE(J489),'Site Info'!$A:$G,7,FALSE),"") -> 8013749700
... A802: GENSUS080E61 | B802: 7.189.252.176 | C802: 842AFD080E61 | D802: S08275 | E802: 46153.082 | F802: 1481 | G802: 8CG107B4ZT | H802: HP_t430 | I802: S08275.US-2016 | J802: =RIGHT(D802,4) -> 8275 | K802: =IFERROR(VLOOKUP(VALUE(J802),'Site Info'!$A:$G,3,FALSE),"") -> 1615 INTERSTATE 10 S | L802: =IFERROR(VLOOKUP(VALUE(J802),'Site Info'!$A:$G,4,FALSE),"") -> BEAUMONT | M802: =IFERROR(VLOOKUP(VALUE(J802),'Site Info'!$A:$G,5,FALSE),"") -> TX | N802: =IFERROR(VLOOKUP(VALUE(J802),'Site Info'!$A:$G,6,FALSE),"") -> 77701-4759 | O802: =IFERROR(VLOOKUP(VALUE(J802),'Site Info'!$A:$G,7,FALSE),"") -> 4098425071
A803: ITC842AFD083B0A | B803: 7.44.212.10 | C803: 842AFD083B0A | D803: S07684 | E803: 46150.799 | F803: 1481 | G803: 8CG12909F5 | H803: HP_t430 | J803: =RIGHT(D803,4) -> 7684 | K803: =IFERROR(VLOOKUP(VALUE(J803),'Site Info'!$A:$G,3,FALSE),"") -> 16150 GOLDEN VLY PKWY | L803: =IFERROR(VLOOKUP(VALUE(J803),'Site Info'!$A:$G,4,FALSE),"") -> LATHROP | M803: =IFERROR(VLOOKUP(VALUE(J803),'Site Info'!$A:$G,5,FALSE),"") -> CA | N803: =IFERROR(VLOOKUP(VALUE(J803),'Site Info'!$A:$G,6,FALSE),"") -> 95330-0000 | O803: =IFERROR(VLOOKUP(VALUE(J803),'Site Info'!$A:$G,7,FALSE),"") -> 2093900324
A804: ITC842AFD08483D | B804: 7.44.212.125 | C804: 842AFD08483D | D804: S07684 | E804: 46152.225 | F804: 1481 | G804: 8CG12909GR | H804: HP_t430 | J804: =RIGHT(D804,4) -> 7684 | K804: =IFERROR(VLOOKUP(VALUE(J804),'Site Info'!$A:$G,3,FALSE),"") -> 16150 GOLDEN VLY PKWY | L804: =IFERROR(VLOOKUP(VALUE(J804),'Site Info'!$A:$G,4,FALSE),"") -> LATHROP | M804: =IFERROR(VLOOKUP(VALUE(J804),'Site Info'!$A:$G,5,FALSE),"") -> CA | N804: =IFERROR(VLOOKUP(VALUE(J804),'Site Info'!$A:$G,6,FALSE),"") -> 95330-0000 | O804: =IFERROR(VLOOKUP(VALUE(J804),'Site Info'!$A:$G,7,FALSE),"") -> 2093900324
A805: GENSUS30FC1F | B805: 7.188.140.212 | C805: C4651630FC1F | D805: S04955 | E805: 46151.876 | F805: 1547 | G805: 8CG9296GZQ | H805: HP_t430 | I805: S04955.US-2016 | J805: =RIGHT(D805,4) -> 4955 | K805: =IFERROR(VLOOKUP(VALUE(J805),'Site Info'!$A:$G,3,FALSE),"") -> 16573 W BELL RD | L805: =IFERROR(VLOOKUP(VALUE(J805),'Site Info'!$A:$G,4,FALSE),"") -> SURPRISE | M805: =IFERROR(VLOOKUP(VALUE(J805),'Site Info'!$A:$G,5,FALSE),"") -> AZ | N805: =IFERROR(VLOOKUP(VALUE(J805),'Site Info'!$A:$G,6,FALSE),"") -> 85374-9892 | O805: =IFERROR(VLOOKUP(VALUE(J805),'Site Info'!$A:$G,7,FALSE),"") -> 6235840054
A806: GENSUS30F66C | B806: 7.188.140.201 | C806: C4651630F66C | D806: S04955 | E806: 46152.529 | F806: 1547 | G806: 8CG9294YZ1 | H806: HP_t430 | I806: S04955.US-2016 | J806: =RIGHT(D806,4) -> 4955 | K806: =IFERROR(VLOOKUP(VALUE(J806),'Site Info'!$A:$G,3,FALSE),"") -> 16573 W BELL RD | L806: =IFERROR(VLOOKUP(VALUE(J806),'Site Info'!$A:$G,4,FALSE),"") -> SURPRISE | M806: =IFERROR(VLOOKUP(VALUE(J806),'Site Info'!$A:$G,5,FALSE),"") -> AZ | N806: =IFERROR(VLOOKUP(VALUE(J806),'Site Info'!$A:$G,6,FALSE),"") -> 85374-9892 | O806: =IFERROR(VLOOKUP(VALUE(J806),'Site Info'!$A:$G,7,FALSE),"") -> 6235840054
A807: GENSUS30FF55 | B807: 7.188.140.124 | C807: C4651630FF55 | D807: S04955 | E807: 46152.759 | F807: 1547 | G807: 8CG9295ZLN | H807: HP_t430 | I807: S04955.US-2016 | J807: =RIGHT(D807,4) -> 4955 | K807: =IFERROR(VLOOKUP(VALUE(J807),'Site Info'!$A:$G,3,FALSE),"") -> 16573 W BELL RD | L807: =IFERROR(VLOOKUP(VALUE(J807),'Site Info'!$A:$G,4,FALSE),"") -> SURPRISE | M807: =IFERROR(VLOOKUP(VALUE(J807),'Site Info'!$A:$G,5,FALSE),"") -> AZ | N807: =IFERROR(VLOOKUP(VALUE(J807),'Site Info'!$A:$G,6,FALSE),"") -> 85374-9892 | O807: =IFERROR(VLOOKUP(VALUE(J807),'Site Info'!$A:$G,7,FALSE),"") -> 6235840054
A808: GENSUS30FC8D | B808: 7.188.140.218 | C808: C4651630FC8D | D808: S04955 | E808: 46152.765 | F808: 1547 | G808: 8CG9296H3H | H808: HP_t430 | I808: S04955.US-2016 | J808: =RIGHT(D808,4) -> 4955 | K808: =IFERROR(VLOOKUP(VALUE(J808),'Site Info'!$A:$G,3,FALSE),"") -> 16573 W BELL RD | L808: =IFERROR(VLOOKUP(VALUE(J808),'Site Info'!$A:$G,4,FALSE),"") -> SURPRISE | M808: =IFERROR(VLOOKUP(VALUE(J808),'Site Info'!$A:$G,5,FALSE),"") -> AZ | N808: =IFERROR(VLOOKUP(VALUE(J808),'Site Info'!$A:$G,6,FALSE),"") -> 85374-9892 | O808: =IFERROR(VLOOKUP(VALUE(J808),'Site Info'!$A:$G,7,FALSE),"") -> 6235840054
A809: GENSUS30FC6A | B809: 7.188.140.220 | C809: C4651630FC6A | D809: S04955 | E809: 46152.888 | F809: 1547 | G809: 8CG9296GZP | H809: HP_t430 | I809: S04955.US-2016 | J809: =RIGHT(D809,4) -> 4955 | K809: =IFERROR(VLOOKUP(VALUE(J809),'Site Info'!$A:$G,3,FALSE),"") -> 16573 W BELL RD | L809: =IFERROR(VLOOKUP(VALUE(J809),'Site Info'!$A:$G,4,FALSE),"") -> SURPRISE | M809: =IFERROR(VLOOKUP(VALUE(J809),'Site Info'!$A:$G,5,FALSE),"") -> AZ | N809: =IFERROR(VLOOKUP(VALUE(J809),'Site Info'!$A:$G,6,FALSE),"") -> 85374-9892 | O809: =IFERROR(VLOOKUP(VALUE(J809),'Site Info'!$A:$G,7,FALSE),"") -> 6235840054
A810: GENSUS1682A4 | B810: 7.188.140.203 | C810: 040E3C1682A4 | D810: S04955 | E810: 46153.282 | F810: 1547 | G810: 8CG942F34D | H810: HP_t430 | I810: S04955.US-2016 | J810: =RIGHT(D810,4) -> 4955 | K810: =IFERROR(VLOOKUP(VALUE(J810),'Site Info'!$A:$G,3,FALSE),"") -> 16573 W BELL RD | L810: =IFERROR(VLOOKUP(VALUE(J810),'Site Info'!$A:$G,4,FALSE),"") -> SURPRISE | M810: =IFERROR(VLOOKUP(VALUE(J810),'Site Info'!$A:$G,5,FALSE),"") -> AZ | N810: =IFERROR(VLOOKUP(VALUE(J810),'Site Info'!$A:$G,6,FALSE),"") -> 85374-9892 | O810: =IFERROR(VLOOKUP(VALUE(J810),'Site Info'!$A:$G,7,FALSE),"") -> 6235840054
A811: GENSUS081F87 | B811: 7.188.140.81 | C811: 842AFD081F87 | D811: S04955 | E811: 46152.664 | F811: 1481 | G811: 8CG1132D6P | H811: HP_t430 | I811: S04955.US-2016 | J811: =RIGHT(D811,4) -> 4955 | K811: =IFERROR(VLOOKUP(VALUE(J811),'Site Info'!$A:$G,3,FALSE),"") -> 16573 W BELL RD | L811: =IFERROR(VLOOKUP(VALUE(J811),'Site Info'!$A:$G,4,FALSE),"") -> SURPRISE | M811: =IFERROR(VLOOKUP(VALUE(J811),'Site Info'!$A:$G,5,FALSE),"") -> AZ | N811: =IFERROR(VLOOKUP(VALUE(J811),'Site Info'!$A:$G,6,FALSE),"") -> 85374-9892 | O811: =IFERROR(VLOOKUP(VALUE(J811),'Site Info'!$A:$G,7,FALSE),"") -> 6235840054
A812: GENSUS081197 | B812: 7.188.140.155 | C812: 842AFD081197 | D812: S04955 | E812: 46153.273 | F812: 1481 | G812: 8CG1079XP3 | H812: HP_t430 | I812: S04955.US-2016 | J812: =RIGHT(D812,4) -> 4955 | K812: =IFERROR(VLOOKUP(VALUE(J812),'Site Info'!$A:$G,3,FALSE),"") -> 16573 W BELL RD | L812: =IFERROR(VLOOKUP(VALUE(J812),'Site Info'!$A:$G,4,FALSE),"") -> SURPRISE | M812: =IFERROR(VLOOKUP(VALUE(J812),'Site Info'!$A:$G,5,FALSE),"") -> AZ | N812: =IFERROR(VLOOKUP(VALUE(J812),'Site Info'!$A:$G,6,FALSE),"") -> 85374-9892 | O812: =IFERROR(VLOOKUP(VALUE(J812),'Site Info'!$A:$G,7,FALSE),"") -> 6235840054
A813: GENSUS0810EE | B813: 7.188.140.227 | C813: 842AFD0810EE | D813: S04955 | E813: 46153.281 | F813: 1481 | G813: 8CG1079XP5 | H813: HP_t430 | I813: S04955.US-2016 | J813: =RIGHT(D813,4) -> 4955 | K813: =IFERROR(VLOOKUP(VALUE(J813),'Site Info'!$A:$G,3,FALSE),"") -> 16573 W BELL RD | L813: =IFERROR(VLOOKUP(VALUE(J813),'Site Info'!$A:$G,4,FALSE),"") -> SURPRISE | M813: =IFERROR(VLOOKUP(VALUE(J813),'Site Info'!$A:$G,5,FALSE),"") -> AZ | N813: =IFERROR(VLOOKUP(VALUE(J813),'Site Info'!$A:$G,6,FALSE),"") -> 85374-9892 | O813: =IFERROR(VLOOKUP(VALUE(J813),'Site Info'!$A:$G,7,FALSE),"") -> 6235840054
A814: GENSUS30C097 | B814: 7.151.108.24 | C814: C4651630C097 | D814: S04906 | E814: 46152.508 | F814: 1547 | G814: 8CG9294NT5 | H814: HP_t430 | I814: S04906.US-2016 | J814: =RIGHT(D814,4) -> 4906 | K814: =IFERROR(VLOOKUP(VALUE(J814),'Site Info'!$A:$G,3,FALSE),"") -> 1670 W UNIVERSITY DR | L814: =IFERROR(VLOOKUP(VALUE(J814),'Site Info'!$A:$G,4,FALSE),"") -> MCKINNEY | M814: =IFERROR(VLOOKUP(VALUE(J814),'Site Info'!$A:$G,5,FALSE),"") -> TX | N814: =IFERROR(VLOOKUP(VALUE(J814),'Site Info'!$A:$G,6,FALSE),"") -> 75069-3444 | O814: =IFERROR(VLOOKUP(VALUE(J814),'Site Info'!$A:$G,7,FALSE),"") -> 4699522417
...

Sheet Site Info
A1: Location Number | B1: Banner Desc | C1: Physical Address Line 1 | D1: Physical City | E1: Physical State | F1: Physical Zip Code | G1: Primary Phone
A2: 4041 | B2: Sam's Club | C2: 1900 EAST LINDEN AVENUE | D2: LINDEN | E2: NJ | F2: 07036-1133 | G2: 9085879820
A3: 4109 | B3: Sam's Club | C3: 2861 BEENE BLVD | D3: BOSSIER CITY | E3: LA | F3: 71111-0000 | G3: 3186066004
A4: 4702 | B4: Sam's Club | C4: 155 W EL DORADO BLVD | D4: FRIENDSWOOD | E4: TX | F4: 77546-6502 | G4: 2812864471
A5: 4703 | B5: Sam's Club | C5: 10600 COORS BLVD BYPASS NW | D5: ALBUQUERQUE | E5: NM | F5: 87114-3930 | G5: 5059220046
A6: 4704 | B6: Sam's Club | C6: 7663 N BLACKSTONE AVE | D6: FRESNO | E6: CA | F6: 93720-4306 | G6: 5594460106
A7: 4707 | B7: Sam's Club | C7: 8300 W 135TH ST | D7: OVERLAND PARK | E7: KS | F7: 66223-1143 | G7: 9134021405
A8: 4709 | B8: Sam's Club | C8: 1375 E ONTARIO AVE | D8: CORONA | E8: CA | F8: 92881-6604 | G8: 9515820319
A9: 4710 | B9: Sam's Club | C9: 2444 CHESAPEAKE SQUARE RING RD | D9: CHESAPEAKE | E9: VA | F9: 23321-2173 | G9: 7574650082
A10: 4711 | B10: Sam's Club | C10: 3345 VIRGINIA BEACH BLVD | D10: VIRGINIA BEACH | E10: VA | F10: 23452-5616 | G10: 7576319791
A11: 4712 | B11: Sam's Club | C11: 10488 KATY FWY | D11: HOUSTON | E11: TX | F11: 77043-5106 | G11: 7134685146
A12: 4713 | B12: Sam's Club | C12: 19091 INTERSTATE 45 S | D12: SHENANDOAH | E12: TX | F12: 77385-8748 | G12: 9362711732
A13: 4718 | B13: Sam's Club | C13: 11278 S JORDAN GTWY | D13: SOUTH JORDAN | E13: UT | F13: 84095-4111 | G13: 8015459801
... A614: 8355 | B614: Sam's Club | C614: 501 S COLLEGE ST | D614: CHARLOTTE | E614: NC | F614: 28202-1827 | G614: 4792734000
